---
title: 异常
date: 2020-05-10 10:31:55
tags:
- Java
categories:
- Java
mathjax: true
---

## 什么是异常？

```java
public class Array {
    public static void main(String[] args){
        int a = 10;
        int b = 0;
        // Exception in thread "main" java.lang.ArithmeticException: / by zero
        int c = a/b; 
        System.out.println(a + "/" + b + "=" + c);
    }
}
```

以上程序执行过程中发生了不正常的情况，而这种不正常的情况叫做：**异常**

java语言提供了异常的处理方法，把异常信息打印输出到控制台，供程序员参考。程序员看到异常信息之后，可以对程序进行修改，让程序更加的健壮



## 异常的存在形式

**异常在Java中以类的形式存在，每一个异常类都可以创建对象**

```java
public class Array {
    public static void main(String[] args){
        int a = 10;
        int b = 0;
        //实际上JVM在运行到这里的时候，会new异常对象(隐式的，我们看不见)，并且JVM会将该异常抛出
        //new ArithmeticException("/ by zero") 
        int c = a/b; 
        System.out.println(a + "/" + b + "=" + c);
    }
}
```

我们也可以自己创建个异常对象看看：

```java
public class Array {
    public static void main(String[] args){
        NullPointerException npe = new NullPointerException("空指针异常");
        // java.lang.NullPointerException: 空指针异常
        System.out.println(npe);
    }
}
```



## 异常的继承结构

继承结构以UML图的形式展示：

{% asset_img 1.png %}

上图的异常类并不完全，只是展示了某一部分

在 Java 中，所有的异常都有一个共同的祖先 Throwable（可抛出）

Throwable 有两个重要的子类：**错误和异常**，二者都是 Java 异常处理的重要子类，各自都包含大量子类。不算是错误还是异常，都是可抛出的

**Exception分类两大类：RuntimeException及其子类、Exception的直接子类**

所有的RuntimeException及子类都属于**运行时异常**；其余所有的Exception直接子类都属于**编译时异常**

**所有的异常都发生在运行阶段，因为异常的发生就是new异常对象**。千万不要认为编译时异常发生在编译阶段，它得名“编译时异常”是因为必须对该异常进行处理，如果不处理会编译报错



编译时异常：又被称为受检异常，一般发生的概率比较高，表示必须在编写程序的时候预先对这种异常进行处理，**如果不处理编译器会报错**。对于这种异常，JAVA编译器强制要求我们必需对出现的这些异常进行catch并处理，否则程序就不能编译通过。所以，面对这种异常不管我们是否愿意，只能自己去写一大堆catch块去处理可能的异常。

- 举个例子：看到外面下雨了，出门之前会预料到如果不打伞，可能会生病（生病是一种异常），而且这个异常发生的概率很高，所以出门之前要带一把伞。**“带一把伞”是对“生病异常”发生之前的一种处理方式**。对于一些发生概率较高的异常，需要在运行之前对其进行预处理

运行时异常：又被称为未受检异常，一般发生的概率较低，在编写程序阶段可以选择处理，也可以选择不处理，这些异常一般是**由程序逻辑错误引起**的。**运行时异常的特点是Java编译器不会检查它**。出现运行时异常后，如果没有捕获处理这个异常（即没有catch），系统会把异常一直往上层抛，一直到最上层

- 举个例子：小明走在大街上，可能会被陨石砸到，被陨石砸到是一种异常。但是这种异常发生概率较低，在出门之前没必要提前对这种发生概率较低的异常进行预处理



假设没有编译时异常和运行时异常的区分，会怎么样？

- 所有的异常都需要在编写程序阶段进行预处理，首先这样会很安全，但是太累了，代码里到处都是处理异常的代码



## 两种异常处理方式

- 在方法声明的位置上，使用**throws**关键字，抛给上一级。**谁调用我，我就抛给谁，抛给调用者**。注意：异常发生后，如果一直上抛，抛给了main方法；main方法继续上抛，抛给了调用者JVM，那么就会终止java程序的执行

```java
public class Array {
    public static void main(String[] args){
        // 因为Exception是编译时异常，需要对其进行处理
        // 如果不处理，编译器会报错
        //doSome(); 编译报错，Unhandled exception: java.lang.Exception
        
        // NullPointerException是运行时异常
        // 所以编译的时候不会报错
        doAgain();
    }
    public static void doSome() throws Exception{}
    public static void doAgain() throws NullPointerException{}
}
```

- 使用**try...catch**语句进行异常捕捉



对于上面那个doSome的编译时异常，还是有**两种处理方式**：

**第一种：继续上抛**

```java
public class Array {
    public static void main(String[] args) throws Exception{
        doSome();
    }
    public static void doSome() throws Exception{}
}
```

**第二种：try...catch**

```java
public class Array {
    public static void main(String[] args){
        try {
            doSome();
        } catch (Exception e) {
            e.printStackTrace();
        }
    }
    public static void doSome() throws Exception{}
}
```

举个例子：我是公司的小职员，因为失误导致公司损失1000元，损失1000元可以看成是一个异常发生了，我有两种处理方式：

- 把这件事告诉我的领导（异常上抛）
- 自己掏腰包把这个钱补上（异常的捕捉）



## 深入throws抛出异常

```java
import java.io.FileInputStream;
public class Array {
    public static void main(String[] args){
        //同理，这里也需要对m1上抛的异常进行处理，有两种处理方式
        //如果继续上抛的话，会将异常抛给JVM，那么JVM就会结束程序
        //一般main方法中的不建议继续上抛，用try...catch处理异常
        try{
            //try尝试
            m1();
        }catch(FileNotFoundException e){
            //catch是捕捉异常之后走的分支
            //这段代码可以使用引用e，e指向那个new出来的异常对象
            System.out.println("路径不正确");
        }
    }

    private static void m1() throws FileNotFoundException{
        //同理，这里也需要对m2上抛的异常进行处理，有两种处理方式
        m2();
    }

    private static void m2() throws FileNotFoundException{
        //这里如果不对m3抛出的异常进行处理，下面的代码会报错
        //为了解决，要么捕捉，要么继续上抛异常
        //但是要注意，抛别的异常不行，必须是FileNotFoundException或其父类及以上直至Exception
        //例如:如果throws ClassCastException依旧会报错。但是抛IOException或者Exception时，就不会再报错了
        //throws可以抛出多个异常，用逗号隔开即可。但是基本都是抛出一个异常
        m3();
    }

    private static void m3() throws FileNotFoundException{
        //下述代码调用了一个类的构造方法，编译会报错
        //这个构造方法的声明位置上有：throws FileNotFoundException
        //FileNotFoundException的父类是IOIOException,IOException的父类是Exception
        //所以FileNotFoundException是编译时异常
        //错误原因:编译时异常要求程序员编写程序时必须对它进行处理，不处理编译器就报错
        new FileInputStream("G:\\pringce.github.io\\source\\_posts\\异常\\1.png");
        //所以可以通过throws抛出异常，就不会报错了
    }
}
```

**记住：**

- 一个方法如果选择throws 的处理异常方式，当某一行代码发生异常时，那么整个方法结束。该行代码下面的所有代码将不会执行
- 一个方法如果选择try...catch的处理异常方式，当try中某一行代码发生异常时，该行代码之前的代码可以正常执行，之后的代码不会执行。随后转入catch，catch中所有的代码都会执行。try...catch结束后，该方法的后续代码可以正常执行



## 深入try-catch

```java
public class Array {
    public static void main(String[] args){
        try{
            new FileInputStream("G:\\pringce.github.io\\source\\_posts\\异常\\1.png");
        }catch(FileNotFoundException e){
            //这里只能捕捉FileNotFoundException及其父类以上，直至Exception。如果这里是NullPointerException，依旧会报错
            System.out.println("文件不存在");
        }
    }
}
```

再来个例子：

```java
public class Array {
    public static void main(String[] args){
        try{
            FileInputStream file = new FileInputStream("G:\\pringce.github.io\\source\\_posts\\异常\\1.png");
            
            //read方法在声明处throws IOEception，所以下面可以由两种方式捕捉
            file.read();
        }
        //第一种：捕捉Exception所有异常，但是缺点是不够精确
        //catch(Exception e){
        //     System.out.println("文件不存在");
        //}
        
        //第二种：精确捕捉异常，这种方式比较推荐
        //catch可以写多个
        //catch写多个时，从上到下必须遵循从小到大的原则
        catch(FileNotFoundException e){
            System.out.println("文件不存在");
        }
        catch(IOException ioe){
            System.out.println("读取异常");
        }
    }
```



**如何选择上抛还是捕捉？**

如果需要调用者处理异常，用throws



## 异常对象的常用方法

异常对象有两个非常重要的方法：

- 获取异常简单的描述信息
  - String msg = exception.getMessage();

```java
public class Array {
    public static void main(String[] args){
        NullPointerException e = new NullPointerException("空指针异常");
        String msg = e.getMessage();
        System.out.println(msg); //"空指针异常"
    }
}
```

- 打印异常追踪的堆栈信息
  - exception.printStackTrace();

```java
public class Array {
    public static void main(String[] args){
        NullPointerException e = new NullPointerException("空指针异常");
        // java.lang.NullPointerException: 空指针异常
		// at test.Array.main(Array.java:20)
        // java后台打印异常堆栈追踪信息的时候，采用了异步线程的方式打印
        e.printStackTrace(); 
    }
}
```



## try-catch中的finally子句

- finally子句的代码是最后执行的，并且一定会执行，即使try语句中的代码发生了异常
- finally得和try一起出现，不能单独编写

```java
public class Array {
    public static void main(String[] args){
        try{
            FileInputStream f = new FileInputStream("G:\\pringce.github.io\\source\\_posts\\异常\\1.png");
            
            //会出现空指针异常
            MyStack s = null;
            s.toString();
            
            //流必须要关闭，否则会占用内存
            //但由于上面出现了空指针异常，所以这里不会执行，会存在隐患
            f.close();

        }
        catch(FileNotFoundException e){
            String msg = e.getMessage();
            System.out.println(msg);
        }
        catch(IOException ioe){
            ioe.printStackTrace();
        }
    }
}
```

为解决上述流无法关闭的问题，可以用finally子句：

```java
public class Array {
    public static void main(String[] args){
        //注意在try外面声明，如果在try里面声明，那么finally里面是不能用的
        FileInputStream f = null;
        try{
            f = new FileInputStream("G:\\pringce.github.io\\source\\_posts\\异常\\1.png");

            MyStack s = null;
            s.toString();
        }catch(FileNotFoundException e){
            String msg = e.getMessage();
            System.out.println(msg);
        }finally {
            try {
                f.close();
            } catch (IOException e) {
                e.printStackTrace();
            }if(f != null) {
                try {
                    f.close();
                } catch (IOException e) {
                    e.printStackTrace();
                }
            }
        }
    }
}
```



**try和finally，没有catch也可以执行**

try不能单独使用

```java
public class Array {
    public static void main(String[] args){
        try{
            System.out.println("try");
            return;
            
            //这里会报错，因为存在return，所以程序运行不到这里
            //System.out.println("xixi");
        }finally {
            System.out.println("finally");
        }
    }
}
//运行结果:
//	try
//	finally
```

上述代码的执行顺序：先输出try，再输出finally，最后return

**finally无论怎样都会执行！！！**



**但是！！！退出JVM，finally语句不执行**

```java
public class Array {
    public static void main(String[] args){
        try{
            System.out.println("try");
            System.exit(0);
        }finally {
            System.out.println("finally");
        }
    }
}
//运行结果:
//	try
```



## 自定义异常

Java内置的异常肯定是不够用的，在实际的开发中，有很多业务出现异常之后，JDK中都是没有的。那么程序员可以自定义异常类



**如何自定义异常？**

- 第一步：编写一个类继承Exception（编译时异常）或RunTimeException（运行时异常）
- 提供两个构造方法，一个无参数的，一个带有String参数的

如下所示：

```java
public class MyException1 extends Exception{//编译时异常
    public MyException1(){
        super();
    };
    public MyException1(String s){
        super(s);
    }
}

public class MyException2 extends RunTimeException{//运行时异常
    
}

```



**自定义异常在开发中的作用**

参考用数组模拟栈的例子：

```java
public class MyStack{
    private int[] elements;
    private int top = -1;
    
    public MyStack() {
        this.elements = new int[10];
    }
    
    public void push(int obj){
        if(top == elements.length-1){
            System.out.println("栈满了");
            return;
        }
        elements[++top] = obj;
    }

    public void pop(){
        if(top < 0){
            System.out.println("栈为空");
            return;
        }
        top--;
    }
}
```

上面的push和pop里面的“栈满了”和“栈为空”是异常，我们可以对上面的写法进行改进：

```java
public class Array  extends MyStack{

    public static void main(String[] args){
        MyStack stack  = new MyStack();
        try {
            for(int i=0;i<=10;i++)
                stack.push(i);
        } catch (MyStackOperationException e) {
            //MyStackOperationException: 栈已满
            e.printStackTrace();
        }
    }
}

class MyStack{
    private int[] elements;
    private int top = -1;
    
    public MyStack() {
        this.elements = new int[10];
    }

    public void push(int obj) throws MyStackOperationException{
        if(top == elements.length-1)
            //手动抛异常
            throw new MyStackOperationException("栈已满");
        elements[++top] = obj;
    }

    public void pop() throws MyStackOperationException{
        if(top < 0){
            //手动抛异常
            throw new MyStackOperationException("栈已空");
        }
        top--;
    }
}

class MyStackOperationException extends Exception{
        public MyStackOperationException(){
        super();
    };
    public MyStackOperationException(String s){
        super(s);
    }
}
```

**这种自定义异常在开发中的应用非常重要！！！**



**总结异常中的关键字：**

- 异常捕捉
  - try
  - catch
  - finally
- throws：在方法声明位置上使用，表示上报异常信息给调用者
- throw：手动抛出异常